Time slot   0
ld_routine
Time slot   1
	Loaded a process at input/proc/p0s, PID: 1 PRIO: 130
	CPU 1: Dispatched process  1
Time slot   2
	Loaded a process at input/proc/m0s, PID: 2 PRIO: 120
	CPU 2: Dispatched process  2
liballoc:178
print_pgtbl:
 PDG=86b00d000 P4g=86b00e000 PUD=86b00f000 PMD=86b010000
liballoc:178
print_pgtbl:
 PDG=86b008000 P4g=86b009000 PUD=86b00a000 PMD=86b00b000
Time slot   3
	CPU 1: Put process  1 to run queue
	CPU 1: Dispatched process  1
liballoc:178
print_pgtbl:
 PDG=86b00d000 P4g=86b00e000 PUD=86b00f000 PMD=86b010000
liballoc:178
print_pgtbl:
 PDG=86b008000 P4g=86b009000 PUD=86b00a000 PMD=86b00b000
Time slot   4
	Loaded a process at input/proc/s3, PID: 3 PRIO: 39
	CPU 2: Put process  2 to run queue
libfree:218
print_pgtbl:
 PDG=86b008000 P4g=86b009000 PUD=86b00a000 PMD=86b00b000
	CPU 2: Dispatched process  2
libfree:218
	CPU 3: Dispatched process  3
print_pgtbl:
 PDG=86b00d000 P4g=86b00e000 PUD=86b00f000 PMD=86b010000
Time slot   5
	Loaded a process at input/proc/s0, PID: 4 PRIO: 38
	CPU 1: Put process  1 to run queue
	CPU 1: Dispatched process  1
	CPU 0: Dispatched process  4
liballoc:178
print_pgtbl:
 PDG=86b008000 P4g=86b009000 PUD=86b00a000 PMD=86b00b000
liballoc:178
print_pgtbl:
 PDG=86b00d000 P4g=86b00e000 PUD=86b00f000 PMD=86b010000
Time slot   6
	CPU 2: Put process  2 to run queue
libwrite:502
print_pgtbl:
 PDG=86b008000 P4g=86b009000 PUD=86b00a000 PMD=86b00b000
	CPU 3: Put process  3 to run queue
	CPU 3: Dispatched process  3
	CPU 2: Dispatched process  2
libwrite:502
print_pgtbl:
 PDG=86b00d000 P4g=86b00e000 PUD=86b00f000 PMD=86b010000
Time slot   7
	CPU 1: Put process  1 to run queue
	CPU 1: Dispatched process  1
libread:426
print_pgtbl:
 PDG=86b008000 P4g=86b009000 PUD=86b00a000 PMD=86b00b000
libwrite:502
print_pgtbl:
 PDG=86b00d000 P4g=86b00e000 PUD=86b00f000 PMD=86b010000
	CPU 0: Put process  4 to run queue
	CPU 0: Dispatched process  4
Time slot   8
	CPU 3: Put process  3 to run queue
	CPU 3: Dispatched process  3
libwrite:502
print_pgtbl:
 PDG=86b008000 P4g=86b009000 PUD=86b00a000 PMD=86b00b000
	CPU 2: Processed  2 has finished
Time slot   9
	Loaded a process at input/proc/m1s, PID: 5 PRIO: 15
	CPU 2: Dispatched process  5
liballoc:178
print_pgtbl:
 PDG=86b01c000 P4g=86b01d000 PUD=86b01e000 PMD=86b01f000
	CPU 0: Put process  4 to run queue
	CPU 0: Dispatched process  4
	CPU 1: Put process  1 to run queue
	CPU 1: Dispatched process  1
libread:426
print_pgtbl:
 PDG=86b008000 P4g=86b009000 PUD=86b00a000 PMD=86b00b000
Time slot  10
liballoc:178
print_pgtbl:
 PDG=86b01c000 P4g=86b01d000 PUD=86b01e000 PMD=86b01f000
libwrite:502
print_pgtbl:
 PDG=86b008000 P4g=86b009000 PUD=86b00a000 PMD=86b00b000
	CPU 3: Put process  3 to run queue
	CPU 3: Dispatched process  3
Time slot  11
	Loaded a process at input/proc/p1s, PID: 6 PRIO: 15
	CPU 0: Put process  4 to run queue
	CPU 0: Dispatched process  6
	CPU 2: Put process  5 to run queue
	CPU 2: Dispatched process  5
libfree:218
print_pgtbl:
 PDG=86b01c000 P4g=86b01d000 PUD=86b01e000 PMD=86b01f000
	CPU 1: Put process  1 to run queue
	CPU 1: Dispatched process  4
Time slot  12
liballoc:178
print_pgtbl:
	CPU 3: Put process  3 to run queue
	CPU 3: Dispatched process  3
 PDG=86b01c000 P4g=86b01d000 PUD=86b01e000 PMD=86b01f000
Time slot  13
	Loaded a process at input/proc/s2, PID: 7 PRIO: 120
	CPU 2: Put process  5 to run queue
	CPU 2: Dispatched process  5
	CPU 1: Put process  4 to run queue
	CPU 1: Dispatched process  4
libfree:218
print_pgtbl:
 PDG=86b01c000 P4g=86b01d000 PUD=86b01e000 PMD=86b01f000
	CPU 0: Put process  6 to run queue
	CPU 0: Dispatched process  6
Time slot  14
	CPU 3: Put process  3 to run queue
	CPU 3: Dispatched process  3
libfree:218
print_pgtbl:
 PDG=86b01c000 P4g=86b01d000 PUD=86b01e000 PMD=86b01f000
Time slot  15
	CPU 1: Put process  4 to run queue
	CPU 1: Dispatched process  4
	CPU 0: Put process  6 to run queue
	CPU 0: Dispatched process  6
	CPU 2: Processed  5 has finished
	CPU 2: Dispatched process  7
Time slot  16
	Loaded a process at input/proc/s1, PID: 8 PRIO: 0
	CPU 3: Put process  3 to run queue
	CPU 3: Dispatched process  8
Time slot  17
	CPU 2: Put process  7 to run queue
	CPU 0: Put process  6 to run queue
	CPU 0: Dispatched process  6
	CPU 2: Dispatched process  3
	CPU 1: Put process  4 to run queue
	CPU 1: Dispatched process  4
Time slot  18
	CPU 3: Put process  8 to run queue
	CPU 3: Dispatched process  8
Time slot  19
	CPU 2: Put process  3 to run queue
	CPU 2: Dispatched process  3
	CPU 1: Put process  4 to run queue
	CPU 1: Dispatched process  4
	CPU 0: Put process  6 to run queue
	CPU 0: Dispatched process  6
Time slot  20
	CPU 3: Put process  8 to run queue
	CPU 3: Dispatched process  8
	CPU 1: Processed  4 has finished
	CPU 1: Dispatched process  7
Time slot  21
	CPU 2: Processed  3 has finished
	CPU 2: Dispatched process  1
libread:426
print_pgtbl:
 PDG=86b008000 P4g=86b009000 PUD=86b00a000 PMD=86b00b000
	CPU 0: Put process  6 to run queue
	CPU 0: Dispatched process  6
Time slot  22
	CPU 3: Put process  8 to run queue
	CPU 3: Dispatched process  8
	CPU 1: Put process  7 to run queue
	CPU 1: Dispatched process  7
Time slot  23
	CPU 2: Put process  1 to run queue
	CPU 2: Dispatched process  1
libfree:218
print_pgtbl:
 PDG=86b008000 P4g=86b009000 PUD=86b00a000 PMD=86b00b000
	CPU 0: Put process  6 to run queue
	CPU 0: Dispatched process  6
Time slot  24
	CPU 3: Put process  8 to run queue
	CPU 3: Dispatched process  8
	CPU 1: Put process  7 to run queue
	CPU 1: Dispatched process  7
Time slot  25
	CPU 3: Processed  8 has finished
	CPU 0: Put process  6 to run queue
	CPU 0: Dispatched process  6
	CPU 2: Processed  1 has finished
	CPU 2 stopped
	CPU 3 stopped
Time slot  26
	CPU 1: Put process  7 to run queue
	CPU 1: Dispatched process  7
Time slot  27
	CPU 0: Put process  6 to run queue
	CPU 0: Dispatched process  6
Time slot  28
	CPU 1: Put process  7 to run queue
	CPU 1: Dispatched process  7
Time slot  29
	CPU 0: Put process  6 to run queue
	CPU 0: Dispatched process  6
Time slot  30
	CPU 1: Processed  7 has finished
	CPU 1 stopped
	CPU 0: Processed  6 has finished
	CPU 0 stopped
